// Answer 0

#[test]
fn test_serialize_some_with_failure() {
    struct FailingSerialize;

    impl Serialize for FailingSerialize {
        fn serialize<S>(&self, _: S) -> Result<Content, S::Error>
        where
            S: Serializer,
        {
            Err(S::Error::custom("Serialization failed"))
        }
    }

    let serializer = ContentSerializer { error: PhantomData };
    let value = FailingSerialize;

    let result: Result<Content, _> = serializer.serialize_some(&value);
    let _ = result; // Use the result to suppress unused variable warning
}

#[test]
fn test_serialize_some_with_another_failure() {
    struct AnotherFailingSerialize;

    impl Serialize for AnotherFailingSerialize {
        fn serialize<S>(&self, _: S) -> Result<Content, S::Error>
        where
            S: Serializer,
        {
            Err(S::Error::custom("Another serialization failure"))
        }
    }

    let serializer = ContentSerializer { error: PhantomData };
    let value = AnotherFailingSerialize;

    let result: Result<Content, _> = serializer.serialize_some(&value);
    let _ = result; // Use the result to suppress unused variable warning
}

